Workbook

Sheet groupe
A1: ETU003082 | B1: ANDRIAMANANTENA Falisoa Haris Ryan
A2: ETU003224 | B2: RAZANAKOTO Miharisoa Hasimanitriniaina

Sheet to_do
A1: Catégorie | B1: Module | C1: Pages | D1: Taches | E1: Type | F1: Qui | G1: Estimation | H1: Temps passé | I1: Reste à faire | J1: Avancement
A2: Shared | B2: Conception | D2: MCD looping | E2: Base | F2: ETU003224 | G2: 10 | H2: =detail_avancement!B2 -> 10 | I2: 0 | J2: =IFERROR(ROUND(H2/(H2+I2),2), "") -> 1
A3: Shared | B3: Initialisation | D3: Initialisation du projet + Docker + init commit sur GITHUB | E3: Init | F3: ETU003082 | G3: 15 | H3: =detail_avancement!B3 -> 15 | I3: 0 | J3: =IFERROR(ROUND(H3/(H3+I3),2), "") -> 1
A4: Shared | B4: Initialisation | D4: Creation des models suivant le MCD (constructors + getters + setters) | E4: Init | F4: ETU003082 | G4: 15 | H4: =detail_avancement!B4 -> 15 | I4: 0 | J4: =IFERROR(ROUND(H4/(H4+I4),2), "") -> 1
A5: Backoffice | B5: Article management | C5: article-add | D5: Form Create (Use TinyMCE) | E5: Affichage | F5: ETU003082 | G5: 15 | H5: =detail_avancement!B5 -> 10 | I5: 0 | J5: =IFERROR(ROUND(H5/(H5+I5),2), "") -> 1
A6: Backoffice | B6: Article management | C6: article-edit | D6: Form Edit (Use TinyMCE again) | E6: Affichage | F6: ETU003082 | G6: 10 | H6: =detail_avancement!B6 -> 15 | I6: 0 | J6: =IFERROR(ROUND(H6/(H6+I6),2), "") -> 1
A7: Backoffice | B7: Article management | C7: article-list-admin | D7: List Article | E7: Affichage | F7: ETU003224 | G7: 15 | H7: =detail_avancement!B7 -> 15 | I7: 0 | J7: =IFERROR(ROUND(H7/(H7+I7),2), "") -> 1 | L7: Col | M7: Currently Working on
A8: Backoffice | B8: Article management | C8: article-detail | D8: Consult article | E8: Affichage | F8: ETU003224 | G8: 10 | H8: =detail_avancement!B8 -> 10 | I8: 0 | J8: =IFERROR(ROUND(H8/(H8+I8),2), "") -> 1 | M8: for 3082
A9: Backoffice | B9: Article management | C9: article-list-admin | D9: Button Edit and Delete Article | E9: Affichage | F9: ETU003224 | G9: 2 | H9: =detail_avancement!B9 -> 3 | I9: 0 | J9: =IFERROR(ROUND(H9/(H9+I9),2), "") -> 1 | M9: for 3224
A10: Backoffice | B10: Article management | C10: article-add & edit | D10: Save: Generate Slug title | E10: Metier | F10: ETU003082 | G10: 10 | H10: =detail_avancement!B10 -> 7 | I10: 0 | J10: =IFERROR(ROUND(H10/(H10+I10),2), "") -> 1
A11: Backoffice | B11: Article management | C11: article-add & edit | D11: Save condition: if created_at is null then use date.now(), else do nothing to avoid erasing OG date | E11: Metier | F11: ETU003082 | G11: 5 | H11: =detail_avancement!B11 -> 17 | I11: 0 | J11: =IFERROR(ROUND(H11/(H11+I11),2), "") -> 1
A12: Backoffice | B12: Article management | C12: article-edit | D12: Edit, Delete | E12: Metier | F12: ETU003082 | G12: 5 | H12: =detail_avancement!B12 -> 5 | I12: 0 | J12: =IFERROR(ROUND(H12/(H12+I12),2), "") -> 1
A13: Backoffice | B13: Article management | C13: article-list | D13: Get All | E13: Metier | F13: ETU003224 | G13: 17 | H13: 15 | I13: 0 | J13: =IFERROR(ROUND(H13/(H13+I13),2), "") -> 1
A14: Backoffice | B14: Article management | C14: Article | D14: Integration CUD | E14: Integration | F14: ETU003082 | G14: 40 | H14: 40 | I14: 0 | J14: =IFERROR(ROUND(H14/(H14+I14),2), "") -> 1
A15: Shared | B15: Article management | C15: Article | D15: Integration R | E15: Integration | F15: ETU003224 | G15: 20 | H15: =detail_avancement!B15 -> 20 | I15: 0 | J15: =IFERROR(ROUND(H15/(H15+I15),2), "") -> 1
A16: Shared | B16: User Management | C16: login-form | D16: Form login, mainly for Admin rn + "Visit as guest" option link to access F.O without credentials | E16: Affichage | F16: ETU003082 | G16: 10 | H16: =detail_avancement!B16 -> 10 | I16: 0 | J16: =IFERROR(ROUND(H16/(H16+I16),2), "") -> 1
A17: Shared | B17: User Management | C17: login-form | D17: "Visit as guest" | E17: Metier | F17: ETU003224 | G17: 5 | H17: =detail_avancement!B17 -> 5 | I17: 0 | J17: =IFERROR(ROUND(H17/(H17+I17),2), "") -> 1
A18: Shared | B18: User Management | C18: login-form | D18: Check login credentials | E18: Metier | F18: ETU003082 | G18: 10 | H18: =detail_avancement!B18 -> 10 | I18: 0 | J18: =IFERROR(ROUND(H18/(H18+I18),2), "") -> 1
A19: Shared | B19: User Management | C19: login-form | D19: Redirect to article-list (guest or other) or redirect to article-list-admin (admin) | E19: Metier | F19: ETU003224 | G19: 3 | H19: =detail_avancement!B19 -> 2 | I19: 0 | J19: =IFERROR(ROUND(H19/(H19+I19),2), "") -> 1
A20: Shared | B20: User Management | C20: login-form | D20: Integration Login | E20: Integration | F20: ETU003224 | G20: 10 | H20: =detail_avancement!B20 -> 10 | I20: 0 | J20: =IFERROR(ROUND(H20/(H20+I20),2), "") -> 1
A22: Frontoffice | B22: Article management | C22: article-list | D22: Copy Paste page from the backoffice but remove the edit, add, delete | E22: Affichage | F22: ETU003224 | G22: 5 | H22: =detail_avancement!B22 -> 3 | I22: 0 | J22: =IFERROR(ROUND(H22/(H22+I22),2), "") -> 1
A23: Frontoffice | B23: Article management | C23: article-detail | D23: Reuse the same page as the one in backoffice | E23: Affichage | F23: ETU003224 | G23: 5 | H23: =detail_avancement!B23 -> 3 | I23: 0 | J23: =IFERROR(ROUND(H23/(H23+I23),2), "") -> 1
A24: Frontoffice | B24: Article management | C24: article-list | D24: Get All: Reuse same func established in the B.O | E24: Metier | F24: ETU003224 | G24: 5 | H24: =detail_avancement!B24 -> 2 | I24: 0 | J24: =IFERROR(ROUND(H24/(H24+I24),2), "") -> 1
A25: Frontoffice | B25: Article management | C25: article-detail | D25: Get Specific Article | E25: Metier | F25: ETU003224 | G25: 10 | H25: =detail_avancement!B25 -> 10 | I25: 0 | J25: =IFERROR(ROUND(H25/(H25+I25),2), "") -> 1
A26: Frontoffice | B26: Article management | C26: article-detail | D26: Get Spe.Arti: Rewrite URL using < ID-Created_At-Slug>.html format | E26: Metier | F26: ETU003224 | G26: 10 | H26: =detail_avancement!B26 -> 10 | I26: 0 | J26: =IFERROR(ROUND(H26/(H26+I26),2), "") -> 1
A27: Frontoffice | B27: Article management | C27: article-detail | D27: Get Spe.Arti: Set the content of the "article-detail" page to the Article.content | E27: Integration | F27: ETU003224 | G27: 10 | H27: =detail_avancement!B27 -> 10 | I27: 0 | J27: =IFERROR(ROUND(H27/(H27+I27),2), "") -> 1
... A30: Backoffice | B30: Article management | C30: article-add & edit | D30: uploadImage: optimization of image size + jpg compression (changed to webp in the end) | E30: Metier | F30: ETU003082 | G30: 15 | H30: =detail_avancement!B30 -> 15 | I30: 0 | J30: =IFERROR(ROUND(H30/(H30+I30),2), "") -> 1
A32: Backoffice | B32: Refactorisation | D32: Refactor all the previous Java Spring Boot -> Php Vanilla w/ AI help | E32: Affichage | F32: ETU003082 | G32: 20 | H32: =detail_avancement!B32 -> 20 | I32: 0 | J32: =IFERROR(ROUND(H32/(H32+I32),2), "") -> 1
A33: Backoffice | B33: Refactorisation | D33: Refactor all the previous Java Spring Boot -> Php Vanilla w/ AI help | E33: Metier | F33: ETU003082 | G33: 25 | H33: =detail_avancement!B33 -> 25 | I33: 0 | J33: =IFERROR(ROUND(H33/(H33+I33),2), "") -> 1
A34: Backoffice | B34: Refactorisation | D34: Refactor all the previous Java Spring Boot -> Php Vanilla w/ AI help | E34: Integration | F34: ETU003082 | G34: 35 | H34: =detail_avancement!B34 -> 35 | I34: 0 | J34: =IFERROR(ROUND(H34/(H34+I34),2), "") -> 1
A36: Shared | B36: Optimisation | D36: compression gzip | E36: Metier | F36: ETU003224 | G36: 5 | H36: =detail_avancement!B36 -> 5 | I36: 0 | J36: =IFERROR(ROUND(H36/(H36+I36),2), "") -> 1
A37: Shared | B37: Optimisation | D37: ajout de balise meta | E37: Metier | F37: ETU003224 | G37: 5 | H37: =detail_avancement!B37 -> 5 | I37: 0 | J37: =IFERROR(ROUND(H37/(H37+I37),2), "") -> 1
A38: Shared | B38: Optimisation | D38: cdn to local font + js | E38: Metier | F38: ETU003082 | G38: 5 | H38: =detail_avancement!B38 -> 5 | I38: 0 | J38: =IFERROR(ROUND(H38/(H38+I38),2), "") -> 1
A39: Shared | B39: Optimisation | D39: minify css | E39: Metier | F39: ETU003082 | G39: 5 | H39: =detail_avancement!B39 -> 5 | I39: 0 | J39: =IFERROR(ROUND(H39/(H39+I39),2), "") -> 1
A40: Shared | B40: Optimisation | D40: caching js and css | E40: Metier | F40: ETU003082 | G40: 5 | H40: =detail_avancement!B40 -> 5 | I40: 0 | J40: =IFERROR(ROUND(H40/(H40+I40),2), "") -> 1
A42: Backoffice | B42: Fix | C42: article-list-admin | D42: fix list redirection if connected as admin (only show the list for the admin, not the guest's) | E42: Metier | F42: ETU003224 | G42: 5 | H42: =detail_avancement!B42 -> 3 | I42: 0 | J42: =IFERROR(ROUND(H42/(H42+I42),2), "") -> 1
A44: Shared | B44: Conception | D44: adding cover image upload | E44: Base | F44: ETU003224 | G44: 5 | H44: =detail_avancement!B44 -> 3 | I44: 0 | J44: =IFERROR(ROUND(H44/(H44+I44),2), "") -> 1
A45: Shared | B45: Article management | C45: article-add | D45: adding cover image upload form | E45: Affichage | F45: ETU003224 | G45: 5 | H45: =detail_avancement!B45 -> 5 | I45: 0 | J45: =IFERROR(ROUND(H45/(H45+I45),2), "") -> 1
A46: Shared | B46: Article management | C46: article-add | D46: handle cover image upload: reuse the imageUpload function, just modify the path to uploads/cover | E46: Metier | F46: ETU003224 | G46: 5 | H46: =detail_avancement!B46 -> 5 | I46: 0 | J46: =IFERROR(ROUND(H46/(H46+I46),2), "") -> 1
A47: Shared | B47: Article management | C47: article-add | D47: adding cover image upload | E47: Integration | F47: ETU003224 | G47: 10 | H47: =detail_avancement!B47 -> 10 | I47: 0 | J47: =IFERROR(ROUND(H47/(H47+I47),2), "") -> 1
...

Sheet recap

Sheet detail_avancement
A1: Ligne | B1: Total | C1: 46110 | D1: 46111 | E1: 46112
A2: 2 | B2: =SUM(C2:Z2) -> 10 | C2: 10
A3: =A2+1 -> 3 | B3: =SUM(C3:Z3) -> 15 | C3: 15
A4: =A3+1 -> 4 | B4: =SUM(C4:Z4) -> 15 | C4: 15
A5: =A4+1 -> 5 | B5: =SUM(C5:Z5) -> 10 | C5: 10
A6: =A5+1 -> 6 | B6: =SUM(C6:Z6) -> 15 | D6: 15
A7: =A6+1 -> 7 | B7: =SUM(C7:Z7) -> 15 | D7: 15
A8: =A7+1 -> 8 | B8: =SUM(C8:Z8) -> 10 | D8: 10
A9: =A8+1 -> 9 | B9: =SUM(C9:Z9) -> 3 | D9: 3
A10: =A9+1 -> 10 | B10: =SUM(C10:Z10) -> 7 | C10: 7
A11: =A10+1 -> 11 | B11: =SUM(C11:Z11) -> 17 | C11: 2 | D11: 15
A12: =A11+1 -> 12 | B12: =SUM(C12:Z12) -> 5 | C12: 5
A13: =A12+1 -> 13 | B13: =SUM(C13:Z13) -> 0
A14: =A13+1 -> 14 | B14: 40 | C14: 20 | D14: 20
A15: =A14+1 -> 15 | B15: =SUM(C15:Z15) -> 20 | D15: 20
A16: =A15+1 -> 16 | B16: =SUM(C16:Z16) -> 10 | D16: 10
A17: =A16+1 -> 17 | B17: =SUM(C17:Z17) -> 5 | D17: 5
A18: =A17+1 -> 18 | B18: =SUM(C18:Z18) -> 10 | D18: 10
A19: =A18+1 -> 19 | B19: =SUM(C19:Z19) -> 2 | D19: 2
A20: =A19+1 -> 20 | B20: =SUM(C20:Z20) -> 10 | D20: 10
A22: 22 | B22: =SUM(C22:Z22) -> 3 | E22: 3
A23: =A22+1 -> 23 | B23: =SUM(C23:Z23) -> 3 | E23: 3
A24: =A23+1 -> 24 | B24: =SUM(C24:Z24) -> 2 | E24: 2
A25: =A24+1 -> 25 | B25: =SUM(C25:Z25) -> 10 | E25: 10
A26: =A25+1 -> 26 | B26: =SUM(C26:Z26) -> 10 | E26: 10
A27: =A26+1 -> 27 | B27: =SUM(C27:Z27) -> 10 | E27: 10
A29: 29 | B29: =SUM(D29:Z29) -> 20 | D29: 20
A30: =A29+1 -> 30 | B30: =SUM(D30:Z30) -> 15 | D30: 15
A32: 32 | B32: =SUM(D32:Z32) -> 20 | D32: 20
A33: =A32+1 -> 33 | B33: =SUM(D33:Z33) -> 25 | D33: 25
A34: =A33+1 -> 34 | B34: =SUM(D34:Z34) -> 35 | D34: 35
A36: 36 | B36: =SUM(D36:Z36) -> 5 | E36: 5
A37: =A36+1 -> 37 | B37: =SUM(D37:Z37) -> 5 | E37: 5
A38: =A37+1 -> 38 | B38: =SUM(D38:Z38) -> 5 | E38: 5
A39: =A38+1 -> 39 | B39: =SUM(D39:Z39) -> 5 | E39: 5
A40: =A39+1 -> 40 | B40: =SUM(D40:Z40) -> 5 | E40: 5
A42: 42 | B42: =SUM(D42:Z42) -> 3 | E42: 3
A44: 44 | B44: =SUM(D44:Z44) -> 3 | E44: 3
A45: =A44+1 -> 45 | B45: =SUM(D45:Z45) -> 5 | E45: 5
A46: =A45+1 -> 46 | B46: =SUM(D46:Z46) -> 5 | E46: 5
...
